<?xml version="1.0" encoding="utf-8"?>
<!-- This URDF was automatically created by SolidWorks to URDF Exporter! Originally created by Stephen Brawner (brawner@gmail.com) 
     Commit Version: 1.6.0-4-g7f85cfe  Build Version: 1.6.7995.38578
     For more information, please see http://wiki.ros.org/sw_urdf_exporter -->
<robot
  name="jawad_model_description">
  <link
    name="base_link">
    <inertial>
      <origin
        xyz="0.0056753 -2.5892E-06 0.020901"
        rpy="0 0 0" />
      <mass
        value="0.56244" />
      <inertia
        ixx="0.0002489"
        ixy="-2.8848E-08"
        ixz="-3.5896E-06"
        iyy="0.0004541"
        iyz="-2.433E-11"
        izz="0.00041921" />
    </inertial>
    <visual>
      <origin
        xyz="0 0 0"
        rpy="0 0 0" />
      <geometry>
        <mesh
          filename="package://jawad_model_description/meshes/base_link.STL" />
      </geometry>
      <material
        name="">
        <color
          rgba="0.75294 0.75294 0.75294 1" />
      </material>
    </visual>
    <collision>
      <origin
        xyz="0 0 0"
        rpy="0 0 0" />
      <geometry>
        <mesh
          filename="package://jawad_model_description/meshes/base_link.STL" />
      </geometry>
    </collision>
  </link>
  <link
    name="link_right_rear">
    <inertial>
      <origin
        xyz="1.38777878078145E-17 -3.46944695195361E-18 -0.00774917307222162"
        rpy="0 0 0" />
      <mass
        value="0.0797111059190679" />
      <inertia
        ixx="3.34957758746331E-05"
        ixy="3.32123569713369E-22"
        ixz="2.42818876898867E-22"
        iyy="3.34955563709507E-05"
        iyz="-7.5137214333458E-23"
        izz="6.32849590567094E-05" />
    </inertial>
    <visual>
      <origin
        xyz="0 0 0"
        rpy="0 0 0" />
      <geometry>
        <mesh
          filename="package://jawad_model_description/meshes/link_right_rear.STL" />
      </geometry>
      <material
        name="">
        <color
          rgba="0.752941176470588 0.752941176470588 0.752941176470588 1" />
      </material>
    </visual>
    <collision>
      <origin
        xyz="0 0 0"
        rpy="0 0 0" />
      <geometry>
        <mesh
          filename="package://jawad_model_description/meshes/link_right_rear.STL" />
      </geometry>
    </collision>
  </link>
  <joint
    name="joint_right_rear"
    type="continuous">
    <origin
      xyz="0.048538 0.06785 0.01615"
      rpy="1.5708 0 -3.1416" />
    <parent
      link="base_link" />
    <child
      link="link_right_rear" />
    <axis
      xyz="0 0 -1" />
    <limit
      effort="20"
      velocity="0.5" />
  </joint>
  <link
    name="link_right_back">
    <inertial>
      <origin
        xyz="0 -3.46944695195361E-18 -0.00774917307222162"
        rpy="0 0 0" />
      <mass
        value="0.0797111059190679" />
      <inertia
        ixx="3.34957758746331E-05"
        ixy="2.24813553269346E-22"
        ixz="8.55748808064149E-23"
        iyy="3.34955563709507E-05"
        iyz="6.7668039898499E-23"
        izz="6.32849590567094E-05" />
    </inertial>
    <visual>
      <origin
        xyz="0 0 0"
        rpy="0 0 0" />
      <geometry>
        <mesh
          filename="package://jawad_model_description/meshes/link_right_back.STL" />
      </geometry>
      <material
        name="">
        <color
          rgba="0.752941176470588 0.752941176470588 0.752941176470588 1" />
      </material>
    </visual>
    <collision>
      <origin
        xyz="0 0 0"
        rpy="0 0 0" />
      <geometry>
        <mesh
          filename="package://jawad_model_description/meshes/link_right_back.STL" />
      </geometry>
    </collision>
  </link>
  <joint
    name="joint_right_back"
    type="continuous">
    <origin
      xyz="-0.051162 0.06785 0.01615"
      rpy="1.5708 0 3.1416" />
    <parent
      link="base_link" />
    <child
      link="link_right_back" />
    <axis
      xyz="0 0 -1" />
    <limit
      effort="20"
      velocity="0.5" />
  </joint>
  <link
    name="link_left_rear">
    <inertial>
      <origin
        xyz="0 -3.46944695195361E-18 -0.00774917307222162"
        rpy="0 0 0" />
      <mass
        value="0.0797111059190679" />
      <inertia
        ixx="3.34957758746331E-05"
        ixy="2.24813553269346E-22"
        ixz="8.56070898530885E-23"
        iyy="3.34955563709507E-05"
        iyz="6.76666819627444E-23"
        izz="6.32849590567094E-05" />
    </inertial>
    <visual>
      <origin
        xyz="0 0 0"
        rpy="0 0 0" />
      <geometry>
        <mesh
          filename="package://jawad_model_description/meshes/link_left_rear.STL" />
      </geometry>
      <material
        name="">
        <color
          rgba="0.752941176470588 0.752941176470588 0.752941176470588 1" />
      </material>
    </visual>
    <collision>
      <origin
        xyz="0 0 0"
        rpy="0 0 0" />
      <geometry>
        <mesh
          filename="package://jawad_model_description/meshes/link_left_rear.STL" />
      </geometry>
    </collision>
  </link>
  <joint
    name="joint_left_rear"
    type="continuous">
    <origin
      xyz="0.048538 -0.06785 0.01615"
      rpy="1.5708 0 0" />
    <parent
      link="base_link" />
    <child
      link="link_left_rear" />
    <axis
      xyz="0 0 -1" />
    <limit
      effort="20"
      velocity="0.5" />
  </joint>
  <link
    name="link_left_back">
    <inertial>
      <origin
        xyz="0 0 0"
        rpy="0 0 0" />
      <mass
        value="0" />
      <inertia
        ixx="0"
        ixy="0"
        ixz="0"
        iyy="0"
        iyz="0"
        izz="0" />
    </inertial>
    <visual>
      <origin
        xyz="0 0 0"
        rpy="0 0 0" />
      <geometry>
        <mesh
          filename="package://jawad_model_description/meshes/link_left_back.STL" />
      </geometry>
      <material
        name="">
        <color
          rgba="1 1 1 1" />
      </material>
    </visual>
    <collision>
      <origin
        xyz="0 0 0"
        rpy="0 0 0" />
      <geometry>
        <mesh
          filename="package://jawad_model_description/meshes/link_left_back.STL" />
      </geometry>
    </collision>
  </link>
  <joint
    name="joint_left_back"
    type="continuous">
    <origin
      xyz="-0.051162 -0.06785 0.01615"
      rpy="1.5708 0 0" />
    <parent
      link="base_link" />
    <child
      link="link_left_back" />
    <axis
      xyz="0 0 -1" />
    <limit
      effort="20"
      velocity="0.5" />
  </joint>
</robot>